<!DOCTYPE html>
<html lang="en">

<head>
    <meta charset="UTF-8">
    <meta http-equiv="X-UA-Compatible" content="IE=edge">
    <meta name="viewport" content="width=device-width, initial-scale=1.0">
    <title>Document</title>
</head>

<body>
    <script>
        const p1 = new Promise((resolve, reject) => {
            try {
                console.log("开始请求A数据");
                throw new Error("Error:网络出现问题")
                setTimeout(() => {
                    console.log("A数据请求成功");
                    resolve(["laowang", "laoyang"])
                }, 2000)
            } catch (e) {
                console.log("报错了,报错信息是", e);
                reject("出现错误" + e);
            }
        })

        /* 
            finally方法：
                - 无论promise实例的状态是成功还是失败调用的finally，都可以进入finally的回调函数进行执行
                - finally的回调函数不需要任何参数

            finally方法的返回值：
                - 如果finally的回调函数没有返回promise实例，则默认都是穿透的
                - 如果finally的回调函数内部出现报错，则直接返回失败的promise实例，值为错误信息
                - 如果finally的回调函数内部返回成功的promise实例，则还是穿透
                - 如果finally的回调函数内部返回失败的promise实例，则finally返回的promise实例直接是失败的，值为内部回调失败promise的值
        */

        const p2 = p1.finally((a) => {
            // throw new Error("error")
            console.log("最后的最后....");
            return new Promise((resolve, reject) => {
                reject(111);
            })
        })

        console.log("p2", p2);
    </script>
</body>

</html>